Traceback (most recent call last):
  File "/root/miniconda/envs/saferew/lib/python3.6/site-packages/pyglet/__init__.py", line 378, in __getattr__
    return getattr(self._module, name)
AttributeError: 'NoneType' object has no attribute 'OrderedGroup'

During handling of the above exception, another exception occurred:

Traceback (most recent call last):
  File "./rdb/examples/run_interactive.py", line 186, in <module>
    main()
  File "./rdb/examples/run_interactive.py", line 69, in main
    max_batch=EVAL_ARGS["max_batch"],
  File "/dar_payload/rdb/rdb/distrib/particles.py", line 104, in __init__
    self._env = env_fn()
  File "./rdb/examples/run_interactive.py", line 37, in env_fn
    env = gym.make(env_name)
  File "/root/miniconda/envs/saferew/lib/python3.6/site-packages/gym/envs/registration.py", line 142, in make
    return registry.make(id, **kwargs)
  File "/root/miniconda/envs/saferew/lib/python3.6/site-packages/gym/envs/registration.py", line 87, in make
    env = spec.make(**kwargs)
  File "/root/miniconda/envs/saferew/lib/python3.6/site-packages/gym/envs/registration.py", line 59, in make
    env = cls(**_kwargs)
  File "/dar_payload/rdb/rdb/envs/drive2d/worlds/week6.py", line 538, in __init__
    task_naturalness=task_naturalness,
  File "/dar_payload/rdb/rdb/envs/drive2d/worlds/week6.py", line 66, in __init__
    super().__init__(main_car, cars, num_lanes=num_lanes, objects=objs, dt=dt)
  File "/dar_payload/rdb/rdb/envs/drive2d/worlds/highway.py", line 31, in __init__
    super().__init__(main_car, cars, self._lanes, dt, objects=objects)
  File "/dar_payload/rdb/rdb/envs/drive2d/core/world.py", line 83, in __init__
    self._layers = utils.EnvGroups()
  File "/dar_payload/rdb/rdb/envs/drive2d/core/utils.py", line 14, in __init__
    self._background = pyglet.graphics.OrderedGroup(0)
  File "/root/miniconda/envs/saferew/lib/python3.6/site-packages/pyglet/__init__.py", line 384, in __getattr__
    __import__(import_name)
  File "/root/miniconda/envs/saferew/lib/python3.6/site-packages/pyglet/graphics/__init__.py", line 170, in <module>
    from pyglet.gl import *
  File "/root/miniconda/envs/saferew/lib/python3.6/site-packages/pyglet/gl/__init__.py", line 239, in <module>
    import pyglet.window
  File "/root/miniconda/envs/saferew/lib/python3.6/site-packages/pyglet/window/__init__.py", line 1896, in <module>
    gl._create_shadow_window()
  File "/root/miniconda/envs/saferew/lib/python3.6/site-packages/pyglet/gl/__init__.py", line 208, in _create_shadow_window
    _shadow_window = Window(width=1, height=1, visible=False)
  File "/root/miniconda/envs/saferew/lib/python3.6/site-packages/pyglet/window/xlib/__init__.py", line 166, in __init__
    super(XlibWindow, self).__init__(*args, **kwargs)
  File "/root/miniconda/envs/saferew/lib/python3.6/site-packages/pyglet/window/__init__.py", line 501, in __init__
    display = get_platform().get_default_display()
  File "/root/miniconda/envs/saferew/lib/python3.6/site-packages/pyglet/window/__init__.py", line 1845, in get_default_display
    return pyglet.canvas.get_display()
  File "/root/miniconda/envs/saferew/lib/python3.6/site-packages/pyglet/canvas/__init__.py", line 82, in get_display
    return Display()
  File "/root/miniconda/envs/saferew/lib/python3.6/site-packages/pyglet/canvas/xlib.py", line 86, in __init__
    raise NoSuchDisplayException('Cannot connect to "%s"' % name)
pyglet.canvas.xlib.NoSuchDisplayException: Cannot connect to "None"
At destination listing 20000...
Finished experiment. Terminating
